Traceback (most recent call last):
  File "C:\Users\14027\anaconda3\Lib\site-packages\jupyter_cache\executors\utils.py", line 58, in single_nb_execution
    executenb(
  File "C:\Users\14027\anaconda3\Lib\site-packages\nbclient\client.py", line 1305, in execute
    return NotebookClient(nb=nb, resources=resources, km=km, **kwargs).execute()
           ^^^^^^^^^^^^^^^^^^^^^^^^^^^^^^^^^^^^^^^^^^^^^^^^^^^^^^^^^^^^^^^^^^^^^
  File "C:\Users\14027\anaconda3\Lib\site-packages\jupyter_core\utils\__init__.py", line 165, in wrapped
    return loop.run_until_complete(inner)
           ^^^^^^^^^^^^^^^^^^^^^^^^^^^^^^
  File "C:\Users\14027\anaconda3\Lib\asyncio\base_events.py", line 654, in run_until_complete
    return future.result()
           ^^^^^^^^^^^^^^^
  File "C:\Users\14027\anaconda3\Lib\site-packages\nbclient\client.py", line 705, in async_execute
    await self.async_execute_cell(
  File "C:\Users\14027\anaconda3\Lib\site-packages\nbclient\client.py", line 1058, in async_execute_cell
    await self._check_raise_for_error(cell, cell_index, exec_reply)
  File "C:\Users\14027\anaconda3\Lib\site-packages\nbclient\client.py", line 914, in _check_raise_for_error
    raise CellExecutionError.from_cell_and_msg(cell, exec_reply_content)
nbclient.exceptions.CellExecutionError: An error occurred while executing the following cell:
------------------
total_df = pd.read_csv('../data/total_df.csv')
tif_harding = rasterio.open('../data/2good harding cove_modified.tif')
tif_keystone = rasterio.open('../data/Keystonetif.tif')
------------------


[1;31m---------------------------------------------------------------------------[0m
[1;31mCPLE_OpenFailedError[0m                      Traceback (most recent call last)
File [1;32mrasterio\\_base.pyx:310[0m, in [0;36mrasterio._base.DatasetBase.__init__[1;34m()[0m

File [1;32mrasterio\\_base.pyx:221[0m, in [0;36mrasterio._base.open_dataset[1;34m()[0m

File [1;32mrasterio\\_err.pyx:359[0m, in [0;36mrasterio._err.exc_wrap_pointer[1;34m()[0m

[1;31mCPLE_OpenFailedError[0m: ../data/2good harding cove_modified.tif: No such file or directory

During handling of the above exception, another exception occurred:

[1;31mRasterioIOError[0m                           Traceback (most recent call last)
Cell [1;32mIn[2], line 2[0m
[0;32m      1[0m total_df [38;5;241m=[39m pd[38;5;241m.[39mread_csv([38;5;124m'[39m[38;5;124m../data/total_df.csv[39m[38;5;124m'[39m)
[1;32m----> 2[0m tif_harding [38;5;241m=[39m rasterio[38;5;241m.[39mopen([38;5;124m'[39m[38;5;124m../data/2good harding cove_modified.tif[39m[38;5;124m'[39m)
[0;32m      3[0m tif_keystone [38;5;241m=[39m rasterio[38;5;241m.[39mopen([38;5;124m'[39m[38;5;124m../data/Keystonetif.tif[39m[38;5;124m'[39m)

File [1;32m~\anaconda3\Lib\site-packages\rasterio\env.py:463[0m, in [0;36mensure_env_with_credentials.<locals>.wrapper[1;34m(*args, **kwds)[0m
[0;32m    460[0m     session [38;5;241m=[39m DummySession()
[0;32m    462[0m [38;5;28;01mwith[39;00m env_ctor(session[38;5;241m=[39msession):
[1;32m--> 463[0m     [38;5;28;01mreturn[39;00m f([38;5;241m*[39margs, [38;5;241m*[39m[38;5;241m*[39mkwds)

File [1;32m~\anaconda3\Lib\site-packages\rasterio\__init__.py:368[0m, in [0;36mopen[1;34m(fp, mode, driver, width, height, count, crs, transform, dtype, nodata, sharing, opener, **kwargs)[0m
[0;32m    365[0m     path [38;5;241m=[39m _parse_path(raw_dataset_path)
[0;32m    367[0m [38;5;28;01mif[39;00m mode [38;5;241m==[39m [38;5;124m"[39m[38;5;124mr[39m[38;5;124m"[39m:
[1;32m--> 368[0m     dataset [38;5;241m=[39m DatasetReader(path, driver[38;5;241m=[39mdriver, sharing[38;5;241m=[39msharing, [38;5;241m*[39m[38;5;241m*[39mkwargs)
[0;32m    369[0m [38;5;28;01melif[39;00m mode [38;5;241m==[39m [38;5;124m"[39m[38;5;124mr+[39m[38;5;124m"[39m:
[0;32m    370[0m     dataset [38;5;241m=[39m get_writer_for_path(path, driver[38;5;241m=[39mdriver)(
[0;32m    371[0m         path, mode, driver[38;5;241m=[39mdriver, sharing[38;5;241m=[39msharing, [38;5;241m*[39m[38;5;241m*[39mkwargs
[0;32m    372[0m     )

File [1;32mrasterio\\_base.pyx:312[0m, in [0;36mrasterio._base.DatasetBase.__init__[1;34m()[0m

[1;31mRasterioIOError[0m: ../data/2good harding cove_modified.tif: No such file or directory

